Traceback (most recent call last):
  File "/usr/local/lib/python3.8/site-packages/jupyter_cache/executors/utils.py", line 51, in single_nb_execution
    executenb(
  File "/usr/local/lib/python3.8/site-packages/nbclient/client.py", line 1265, in execute
    return NotebookClient(nb=nb, resources=resources, km=km, **kwargs).execute()
  File "/usr/local/lib/python3.8/site-packages/jupyter_core/utils/__init__.py", line 160, in wrapped
    return loop.run_until_complete(inner)
  File "/usr/local/Cellar/python@3.8/3.8.5/Frameworks/Python.framework/Versions/3.8/lib/python3.8/asyncio/base_events.py", line 616, in run_until_complete
    return future.result()
  File "/usr/local/lib/python3.8/site-packages/nbclient/client.py", line 703, in async_execute
    await self.async_execute_cell(
  File "/usr/local/lib/python3.8/site-packages/nbclient/client.py", line 1021, in async_execute_cell
    await self._check_raise_for_error(cell, cell_index, exec_reply)
  File "/usr/local/lib/python3.8/site-packages/nbclient/client.py", line 915, in _check_raise_for_error
    raise CellExecutionError.from_cell_and_msg(cell, exec_reply_content)
nbclient.exceptions.CellExecutionError: An error occurred while executing the following cell:
------------------
#main difference from a list!
simple_tuple[2] = 'hardy'
------------------

[0;31m------------------------------------------------------[0m
[0;31mTypeError[0m            Traceback (most recent call last)
Cell [0;32mIn[11], line 2[0m
[1;32m      1[0m [38;5;66;03m#main difference from a list![39;00m
[0;32m----> 2[0m [43msimple_tuple[49m[43m[[49m[38;5;241;43m2[39;49m[43m][49m [38;5;241m=[39m [38;5;124m'[39m[38;5;124mhardy[39m[38;5;124m'[39m

[0;31mTypeError[0m: 'tuple' object does not support item assignment
TypeError: 'tuple' object does not support item assignment

